// Copyright [2022] <@damianWu>

#include <iostream>

int main() {
    try {
    } catch (const std::exception &e) {
        std::cerr << "Exception catch in main function with message: "
                  << e.what() << '\n';
    } catch (...) {
        std::cerr << "Unknown type of exception catch in main function" << '\n';
    }
    return 0;
}
